# Error Handling in JavaScript: `try/catch/finally`

## 8.1 Introduction to Error Handling

Error handling is an essential part of writing reliable JavaScript programs. The **`try/catch/finally`** statement provides a way to handle errors gracefully without crashing your application.

---

### 8.2 `try` Block

The **`try`** block contains the code that may throw an error. If an error occurs in the `try` block, JavaScript immediately jumps to the `catch` block.

#### Example:
```javascript
try {
  const result = someUndefinedFunction();
} catch (error) {
  console.log("An error occurred:", error);
}
// Output: An error occurred: ReferenceError: someUndefinedFunction is not defined
```

---

### 8.3 `catch` Block

The **`catch`** block is executed if an error occurs in the `try` block. It takes an **error object** as a parameter, which contains information about the error.

#### Example:
```javascript
try {
  const result = 10 / 0; // No error, but it's an invalid calculation
  const result2 = someUndefinedFunction(); // This will throw an error
} catch (error) {
  console.log("Error message:", error.message);
  console.log("Error name:", error.name);
}
// Output: 
// Error message: someUndefinedFunction is not defined
// Error name: ReferenceError
```

### Explanation:
- **`error.message`**: Contains the error message, like "someUndefinedFunction is not defined."
- **`error.name`**: Contains the error type, such as `ReferenceError`, `TypeError`, or `SyntaxError`.

---

### 8.4 `finally` Block

The **`finally`** block is executed after the `try` and `catch` blocks, regardless of whether an error occurred. This is useful for cleaning up resources (e.g., closing files, stopping timers) whether an error occurred or not.

#### Example:
```javascript
try {
  const result = someUndefinedFunction();
} catch (error) {
  console.log("An error occurred:", error.message);
} finally {
  console.log("This runs no matter what.");
}
// Output:
// An error occurred: someUndefinedFunction is not defined
// This runs no matter what.
```

### Explanation:
- **`finally`** is executed whether the code in the `try` block throws an error or not.
- It’s often used to release resources or perform cleanup tasks.

---

### 8.5 Optional `catch` Binding (ES10)

Starting from **ES10**, you can omit the `error` parameter in the `catch` block if you don't need to use it.

#### Example:
```javascript
try {
  throw new Error("Oops!");
} catch {
  console.log("An error occurred, but we don't need the error object.");
}
```

---

### 8.6 Throwing Custom Errors

You can use the **`throw`** statement to manually throw custom errors in your code.

#### Example:
```javascript
function divide(a, b) {
  if (b === 0) {
    throw new Error("Cannot divide by zero");
  }
  return a / b;
}

try {
  const result = divide(10, 0);
} catch (error) {
  console.log("Error:", error.message);
}
// Output: Error: Cannot divide by zero
```

### Explanation:
- The `throw` statement generates a custom error, which can then be caught by `catch`.

---

### 8.7 Nested `try/catch/finally` Blocks

You can nest `try/catch/finally` blocks if needed. This can be useful in complex code where different sections may need different error handling.

#### Example:
```javascript
try {
  try {
    throw new Error("Inner error");
  } catch (innerError) {
    console.log("Caught inner error:", innerError.message);
  } finally {
    console.log("Inner finally block.");
  }
  throw new Error("Outer error");
} catch (outerError) {
  console.log("Caught outer error:", outerError.message);
} finally {
  console.log("Outer finally block.");
}

// Output:
// Caught inner error: Inner error
// Inner finally block.
// Caught outer error: Outer error
// Outer finally block.
```

---

### 8.8 When to Use `finally`

- **Releasing Resources**: Clean up resources like file handles, network connections, or timers, regardless of whether an error occurred.
- **Completing Transactions**: In applications with databases, the `finally` block can ensure that a transaction is properly closed.
- **Logging**: Log activity to ensure you know the current state, even in the case of an error.

---

### Summary of `try/catch/finally`

- **`try`**: Contains code that might throw an error.
- **`catch`**: Handles the error if it occurs, using the `error` object to get details about the error.
- **`finally`**: Always executes after `try` and `catch`, useful for cleanup tasks.
- **`throw`**: Manually throw custom errors.
- **Optional `catch` Binding**: In ES10, you can omit the `error` parameter in the `catch` block.

---

### Copyright Notice
© 2024 Andrew Bamford. This work is licensed under a [Creative Commons Attribution 4.0 International License](https://creativecommons.org/licenses/by/4.0/).

You are free to: share, copy, redistribute the material in any medium or format, adapt, remix, transform, and build upon the material for any purpose, even commercially, under the following terms: Attribution – You must give appropriate credit, provide a link to the license, and indicate if changes were made.
